<?xml version="1.0"?>
<robot xmlns:xacro="http://www.ros.org/wiki/xacro" >

    <xacro:include filename="inertial_macros.xacro" />
    
    <material name="white">
        <color rgba="1 1 1 1" />
    </material>

    <material name="orange">
        <color rgba="1 0.3 0.1 1"/>
    </material>

    <material name="blue">
        <color rgba="0.2 0.2 1 1"/>
    </material>

    <material name="black">
        <color rgba="0 0 0 1"/>
    </material>
    
    <material name="red">
        <color rgba="1 0 0 1"/>
    </material>
    
    <!-- BASE LINK -->

    <link name="base_link">

    </link>
    
    <!-- BASE_FOOTPRINT LINK -->

    <joint name="base_footprint_joint" type="fixed">
        <parent link="base_link"/>
        <child link="base_footprint"/>
        <origin xyz="0 0 0" rpy="0 0 0"/>
    </joint>

    <link name="base_footprint">
    </link>

    <!-- CHASSIS LINK -->

    <joint name="chassis_joint" type="fixed">
        <parent link="base_link"/>
        <child link="chassis"/>
        <origin xyz="-0.085 0 0"/>
    </joint>

    <link name="chassis">
        <visual>
            <origin xyz="0.085 0 0.04"/>
            <geometry>
                <box size="0.17 0.25 0.08"/>
            </geometry>
            <material name="white"/>
        </visual>
        <collision>
            <origin xyz="0.085 0 0.04"/>
            <geometry>
                <box size="0.17 0.25 0.08"/>
            </geometry>
        </collision>
        <xacro:inertial_box mass="0.5" x="0.17" y="0.25" z="0.08">
            <origin xyz="0.085 0 0.04" rpy="0 0 0"/>
        </xacro:inertial_box>
    </link>
    
    <!-- LEFT WHEEL LINK -->

    <joint name="left_wheel_joint" type="continuous">
        <parent link="base_link"/>
        <child link="left_wheel"/>
        <origin xyz="0 0.1395 0" rpy="-${pi/2} 0 0" />
        <axis xyz="0 0 1"/>
    </joint>

    <link name="left_wheel">
        <visual>
            <geometry>
                <cylinder radius="0.0325" length="0.025"/>
            </geometry>
            <material name="blue"/>
        </visual>
        <collision>
            <geometry>
                <cylinder radius="0.0325" length="0.025"/>
            </geometry>
        </collision>
        <xacro:inertial_cylinder mass="0.1" length="0.025" radius="0.0325">
            <origin xyz="0 0 0" rpy="0 0 0"/>
        </xacro:inertial_cylinder>
    </link>

    <!-- RIGHT WHEEL LINK -->

    <joint name="right_wheel_joint" type="continuous">
        <parent link="base_link"/>
        <child link="right_wheel"/>
        <origin xyz="0 -0.1395 0" rpy="${pi/2} 0 0" />
        <axis xyz="0 0 -1"/>
    </joint>

    <link name="right_wheel">
        <visual>
            <geometry>
                <cylinder radius="0.0325" length="0.025"/>
            </geometry>
            <material name="blue"/>
        </visual>
        <collision>
            <geometry>
                <cylinder radius="0.0325" length="0.025"/>
            </geometry>
        </collision>
        <xacro:inertial_cylinder mass="0.1" length="0.025" radius="0.0325">
            <origin xyz="0 0 0" rpy="0 0 0"/>
        </xacro:inertial_cylinder>
    </link>

    <!-- CASTER WHEEL LINK -->

    <joint name="caster_wheel_before_joint" type="fixed">
        <parent link="chassis"/>
        <child link="caster_wheel_before"/>
        <origin xyz="0.13 0 0"/>
    </joint>


    <link name="caster_wheel_before">
        <visual>
            <geometry>
                <sphere radius="0.0325"/>
            </geometry>
            <material name="black"/>
        </visual>
        <collision>
            <geometry>
                <sphere radius="0.0325"/>
            </geometry>
        </collision>
        <xacro:inertial_sphere mass="0.1" radius="0.0325">
            <origin xyz="0 0 0" rpy="0 0 0"/>
        </xacro:inertial_sphere> 
    </link>
    
    <joint name="caster_wheel_after_joint" type="fixed">
        <parent link="chassis"/>
        <child link="caster_wheel_after"/>
        <origin xyz="0.04 0 0"/>
    </joint>


    <link name="caster_wheel_after">
        <visual>
            <geometry>
                <sphere radius="0.0325"/>
            </geometry>
            <material name="black"/>
        </visual>
        <collision>
            <geometry>
                <sphere radius="0.0325"/>
            </geometry>
        </collision>
        <xacro:inertial_sphere mass="0.1" radius="0.0325">
            <origin xyz="0 0 0" rpy="0 0 0"/>
        </xacro:inertial_sphere>
    </link>
    
</robot>
